components: []
created_by: !!python/object:uuid.UUID
  int: 217356799640352244068158184369341070513
created_time: &id001 2011-05-28 16:02:54.756706
description: 'I just crashed while writing a new script because I accidentally hit

  "21" rather than 2 1 when adding tags to my task.


  The choose_from_already_instantiated rightly raised an exception, but

  nothing in the script caught it, so, KABOOM.'
estimate: !!python/object:uuid.UUID
  int: 334988786726400201598883942844016081861
milestone: !!python/object:uuid.UUID
  int: 43202488294965147244317640483158997306
modified_time: *id001
owner: !!python/object:uuid.UUID
  int: 219503519214021148627266826050732492225
pscore: 0
status: !!python/object:uuid.UUID
  int: 327359014471868074244219043980996376403
tags:
- !!python/object:uuid.UUID
  int: 213302401238485658731862796644474871986
title: 'Catch exceptions raised by choose_from_already_instantiated during pitz-add-task

  '
type: task
uuid: !!python/object:uuid.UUID
  int: 154321939961802398414694878354120479964
yaml_file_saved: 2011-05-28 16:02:54.769213
